Workbook

Sheet Лист1
A1: Vanilla guns - Name of 1st gun - Van | B1: Class | C1: hull_damage | D1: energy_damage | E1: power_usage | G1: Vanilla guns - Name of 1st gun - New Balance | H1: hull_damage | I1: energy_damage | J1: power_usage | L1: 10 class | M1: hull_damage | N1: energy_damage | O1: power_usage
A2: ;fc_j_gun01, 2, 30.6 - 0 - 9.18 | B2: 2 | C2: 30.6 | D2: 0 | E2: 9.18 | F2: 1 | G2: ;fc_j_gun01, 2, 30.6 - 0 - 9.18 | H2: =C2/H40 -> 20 | I2: 0 | J2: =E2/$I$40 -> 7.344 | L2: special_gun01 | M2: 1075.8 | N2: 0 | O2: 268.95
A3: ;fc_lr_gun01, 1, 19.6 - 0 - 6.11 | B3: 1 | C3: 19.6 | D3: 0 | E3: 6.11 | F3: 2 | G3: ;fc_lr_gun01, 1, 19.6 - 0 - 6.11 | H3: =C3 -> 19.6 | I3: 0 | J3: =E3/$I$40 -> 4.888 | L3: special_gun02 | M3: 880.2 | N3: 0 | O3: 220.05
A4: ;fc_ou_gun01, 1, 126.4 - 0 - 31.6 | B4: 1 | C4: 126.4 | D4: 0 | E4: 31.6 | F4: 3 | G4: ;fc_ou_gun01, 1, 126.4 - 0 - 31.6 | H4: =C4 -> 126.4 | I4: 0 | J4: =E4/$I$40 -> 25.28 | L4: special_gun03 | M4: 652 | N4: 0 | O4: 163
A5: ;fc_ou_gun02, 5, 113.8 - 0 - 23.7 | B5: 5 | C5: 113.8 | D5: 0 | E5: 23.7 | F5: 4 | G5: ;fc_ou_gun02, 5, 113.8 - 0 - 23.7 | H5: =C5/$H$43 -> 37.592268 | I5: 0 | J5: =E5/$I$43 -> 9.5912278 | L5: special_gun04 | M5: 1173.6 | N5: 0 | O5: 293.4
A6: ;fc_c_gun01, 5, 121.2 - 0 - 24.24 | B6: 5 | C6: 121.2 | D6: 0 | E6: 24.24 | F6: 5 | G6: ;fc_c_gun01, 5, 121.2 - 0 - 24.24 | H6: =C6/$H$43 -> 40.036756 | I6: 0 | J6: =E6/$I$43 -> 9.8097621 | L6: special_gun05 | M6: 880.2 | N6: 0 | O6: 220.05
A7: ;fc_c_gun02, 5, 10.1 - 303 - 24.24 | B7: 5 | C7: 10.1 | D7: 303 | E7: 24.24 | F7: 6 | G7: ;fc_c_gun02, 5, 10.1 - 303 - 24.24 | H7: =C7/$H$43 -> 3.3363963 | I7: =D7/H43 -> 100.09189 | J7: =E7/$I$43 -> 9.8097621 | L7: special_gun06 | M7: 717.2 | N7: 0 | O7: 179.3
A8: ;fc_or_gun01, 5, 40.4 - 0 - 12.62 | B8: 5 | C8: 40.4 | D8: 0 | E8: 12.62 | F8: 7 | G8: ;fc_or_gun01, 5, 40.4 - 0 - 12.62 | H8: =C8/$H$43 -> 13.345585 | I8: 0 | J8: =E8/$I$43 -> 5.1072276 | L8: special_gun07 | M8: 782.4 | N8: 0 | O8: 195.6
A9: ;fc_or_gun02, 5, 101 - 0 - 20.2 | B9: 5 | C9: 101 | D9: 0 | E9: 20.2 | F9: 8 | G9: ;fc_or_gun02, 5, 101 - 0 - 20.2 | H9: =C9/$H$43 -> 33.363963 | I9: 0 | J9: =E9/$I$43 -> 8.1748018 | L9: special_gun08 | M9: 1075.8 | N9: 0 | O9: 244.5
A10: ;gd_gm_gun01, 6, 79.1 - 0 - 19.76 | B10: 6 | C10: 79.1 | D10: 0 | E10: 19.76 | F10: 9 | G10: ;gd_gm_gun01, 6, 79.1 - 0 - 19.76 | H10: =C10/$H$44 -> 20.099692 | I10: 0 | J10: =E10/$I$44 -> 6.1277676 | L10: special_gun09 | M10: 978 | N10: 0 | O10: 268.95
A11: ;gd_im_gun01, 3, 49.8 - 0 - 14.94 | B11: 3 | C11: 49.8 | D11: 0 | E11: 14.94 | F11: 10 | G11: ;gd_im_gun01, 3, 49.8 - 0 - 14.94 | H11: =C11/$H$41 -> 26.679524 | I11: 0 | J11: =E11/$I$41 -> 9.804758 | L11: special_gun10 | M11: 1075.8 | N11: 0 | O11: 220.05
A12: ;gd_bh_gun01, 2, 20.4 - 0 - 7.65 | B12: 2 | C12: 20.4 | D12: 0 | E12: 7.65 | F12: 11 | G12: ;gd_bh_gun01, 2, 20.4 - 0 - 7.65 | H12: =C12/$H$40 -> 13.333333 | I12: 0 | J12: =E12/$I$40 -> 6.12 | L12: special_gun11 | M12: 880.2 | N12: 0 | O12: 244.5
A13: ;gd_bh_gun02, 2, 49 - 0 - 15.3 | B13: 2 | C13: 49 | D13: 0 | E13: 15.3 | F13: 12 | G13: ;gd_bh_gun02, 2, 49 - 0 - 15.3 | H13: =C13/$H$40 -> 32.026144 | I13: 0 | J13: =E13/$I$40 -> 12.24 | L13: special_gun12 | M13: 586.8 | N13: 0 | O13: 146.7
A14: ;fc_rh_gun01, 5, 53.9 - 0 - 16.83 | B14: 5 | C14: 53.9 | D14: 0 | E14: 16.83 | F14: 13 | G14: ;fc_rh_gun01, 5, 53.9 - 0 - 16.83 | H14: =C14/$H$43 -> 17.805125 | I14: 0 | J14: =E14/$I$40 -> 13.464 | L14: special_gun13 | M14: 1075.8 | N14: 0 | O14: 268.95
A15: ;fc_bd_gun01, 5, 40.4 - 0 - 12.62 | B15: 5 | C15: 40.4 | D15: 0 | E15: 12.62 | F15: 14 | G15: ;fc_bd_gun01, 5, 40.4 - 0 - 12.62 | H15: =C15/$H$43 -> 13.345585 | I15: 0 | J15: =E15/$I$43 -> 5.1072276 | L15: special_gun14 | M15: 1173.6 | N15: 0 | O15: 293.4
A16: ;fc_b_gun01, 6, 210.8 - 0 - 52.7 | B16: 6 | C16: 210.8 | D16: 0 | E16: 52.7 | F16: 15 | G16: ;fc_b_gun01, 6, 210.8 - 0 - 52.7 | H16: =C16/$H$45 -> 40.57977 | I16: 0 | J16: =E16/$I$44 -> 16.342781 | L16: special_gun15 | M16: 978 | N16: 0 | O16: 268.95
A17: ;gd_z_gun01, 3, 41.5 - 0 - 12.45 | B17: 3 | C17: 41.5 | D17: 0 | E17: 12.45 | F17: 16 | G17: ;gd_z_gun01, 3, 41.5 - 0 - 12.45 | H17: =C17/$H$41 -> 22.232937 | I17: 0 | J17: =E17/$I$41 -> 8.1706317
A18: ;fc_lh_gun01, 4, 79 - 0 - 23.7 | B18: 4 | C18: 79 | D18: 0 | E18: 23.7 | F18: 17 | G18: ;fc_lh_gun01, 4, 79 - 0 - 23.7 | H18: =C18/$H$42 -> 33.351411 | I18: 0 | J18: =E18/$I$42 -> 12.247998 | L18: special_nomad_gun01 | M18: 847.6 | N18: 0 | O18: 0
A19: ;fc_h_gun01, 6, 158.1 - 0 - 32.94 | B19: 6 | C19: 158.1 | D19: 0 | E19: 32.94 | F19: 18 | G19: ;fc_h_gun01, 6, 158.1 - 0 - 32.94 | H19: =C19/$H$45 -> 30.434828 | I19: 0 | J19: =E19/$I$44 -> 10.215013 | L19: special_nomad_gun02 | M19: 302 | N19: 0 | O19: 0
A20: ;fc_m_gun01, 5, 101 - 0 - 20.2 | B20: 5 | C20: 101 | D20: 0 | E20: 20.2 | F20: 19 | G20: ;fc_m_gun01, 5, 101 - 0 - 20.2 | H20: =C20/$H$43 -> 33.363963 | I20: 0 | J20: =E20/$I$43 -> 8.1748018
A21: ;fc_g_gun01, 3, 41.5 - 0 - 9.96 | B21: 3 | C21: 41.5 | D21: 0 | E21: 9.96 | F21: 20 | G21: ;fc_g_gun01, 3, 41.5 - 0 - 9.96 | H21: =C21/$H$41 -> 22.232937 | I21: 0 | J21: =E21/$I$40 -> 7.968
A22: ;fc_u_gun01, 4, 79 - 0 - 15.8 | B22: 4 | C22: 79 | D22: 0 | E22: 15.8 | F22: 21 | G22: ;fc_u_gun01, 4, 79 - 0 - 15.8 | H22: =C22/$H$42 -> 33.351411 | I22: 0 | J22: =E22/$I$42 -> 8.165332
A23: ;fc_gc_gun01, 4, 52.7 - 0 - 15.8 | B23: 4 | C23: 52.7 | D23: 0 | E23: 15.8 | F23: 22 | G23: ;fc_gc_gun01, 4, 52.7 - 0 - 15.8 | H23: =C23/$H$42 -> 22.248346 | I23: 0 | J23: =E23/$I$42 -> 8.165332
A24: ;fc_lwb_gun01, 5, 134.7 - 0 - 32.32 | B24: 5 | C24: 134.7 | D24: 0 | E24: 32.32 | F24: 23 | G24: ;fc_lwb_gun01, 5, 134.7 - 0 - 32.32 | H24: =C24/$H$43 -> 44.496296 | I24: 0 | J24: =E24/$I$43 -> 13.079683 | L24: 6 class | M24: hull_damage | N24: energy_damage | O24: power_usage
A25: ;fc_fa_gun01, 4, 126.4 - 0 - 21.07 | B25: 4 | C25: 126.4 | D25: 0 | E25: 21.07 | F25: 24 | G25: ;fc_fa_gun01, 4, 126.4 - 0 - 21.07 | H25: =C25/$H$42 -> 53.362257 | I25: 0 | J25: =E25/$I$42 -> 10.888832 | L25: special_gun01 | M25: =M2*($H$44/$H$48) -> 282.24572 | N25: =N2*($H$44/$H$48) -> 0 | O25: =O2*($H$44/$H$48) -> 70.561431 | P25: 1
A26: ;fc_x_gun01, 2, 73.4 - 0 - 15.3 | B26: 2 | C26: 73.4 | D26: 0 | E26: 15.3 | F26: 25 | G26: ;fc_x_gun01, 2, 73.4 - 0 - 15.3 | H26: =C26/$H$43 -> 24.246682 | I26: 0 | J26: =E26/$I$40 -> 12.24 | L26: special_gun02 | M26: =M3*($H$44/$H$48) -> 230.92832 | N26: =N3*($H$44/$H$48) -> 0 | O26: =O3*($H$44/$H$48) -> 57.73208 | P26: 2
A27: ;li_gun01, 1, 16.3 - 0 - 5.09 | B27: 1 | C27: 16.3 | D27: 0 | E27: 5.09 | F27: 26 | G27: ;li_gun01, 1, 16.3 - 0 - 5.09 | H27: =C27 -> 16.3 | I27: 0 | J27: =E27/$I$39 -> 5.09 | L27: special_gun03 | M27: =M4*($H$44/$H$48) -> 171.05801 | N27: =N4*($H$44/$H$48) -> 0 | O27: =O4*($H$44/$H$48) -> 42.764504 | P27: 3
A28: ;li_gun02, 1, 97.8 - 0 - 20.38 | B28: 1 | C28: 97.8 | D28: 0 | E28: 20.38 | F28: 27 | G28: ;li_gun02, 1, 97.8 - 0 - 20.38 | H28: =C28 -> 97.8 | I28: 0 | J28: =E28/$I$39 -> 20.38 | L28: special_gun04 | M28: =M5*($H$44/$H$48) -> 307.90443 | N28: =N5*($H$44/$H$48) -> 0 | O28: =O5*($H$44/$H$48) -> 76.976106 | P28: 4
A29: ;br_gun01, 4, 79 - 0 - 23.7 | B29: 4 | C29: 79 | D29: 0 | E29: 23.7 | F29: 28 | G29: ;br_gun01, 4, 79 - 0 - 23.7 | H29: =C29/$H$40 -> 51.633987 | I29: 0 | J29: =E29/$I$42 -> 12.247998 | L29: special_gun05 | M29: =M6*($H$44/$H$48) -> 230.92832 | N29: =N6*($H$44/$H$48) -> 0 | O29: =O6*($H$44/$H$48) -> 57.73208 | P29: 5
A30: ;br_gun02, 4, 94.8 - 0 - 23.7 | B30: 4 | C30: 94.8 | D30: 0 | E30: 23.7 | F30: 29 | G30: ;br_gun02, 4, 94.8 - 0 - 23.7 | H30: =C30/$H$40 -> 61.960784 | I30: 0 | J30: =E30/$I$42 -> 12.247998 | L30: special_gun06 | M30: =M7*($H$44/$H$48) -> 188.16382 | N30: =N7*($H$44/$H$48) -> 0 | O30: =O7*($H$44/$H$48) -> 47.040954 | P30: 6
A31: ;ku_gun01, 5, 101 - 0 - 20.2 | B31: 5 | C31: 101 | D31: 0 | E31: 20.2 | F31: 30 | G31: ;ku_gun01, 5, 101 - 0 - 20.2 | H31: =C31/$H$40 -> 66.013072 | I31: 0 | J31: =E31/$I$43 -> 8.1748018 | L31: special_gun07 | M31: =M8*($H$44/$H$48) -> 205.26962 | N31: =N8*($H$44/$H$48) -> 0 | O31: =O8*($H$44/$H$48) -> 51.317404 | P31: 7
A32: ;ku_gun02, 5, 50.5 - 0 - 15.15 | B32: 5 | C32: 50.5 | D32: 0 | E32: 15.15 | F32: 31 | G32: ;ku_gun02, 5, 50.5 - 0 - 15.15 | H32: =C32/$H$43 -> 16.681982 | I32: 0 | J32: =E32/$I$43 -> 6.1311013 | L32: special_gun08 | M32: =M9*($H$44/$H$48) -> 282.24572 | N32: =N9*($H$44/$H$48) -> 0 | O32: =O9*($H$44/$H$48) -> 64.146755 | P32: 8
A33: ;rh_gun01, 6, 70.3 - 0 - 26.35 | B33: 6 | C33: 70.3 | D33: 0 | E33: 26.35 | F33: 32 | G33: ;rh_gun01, 6, 70.3 - 0 - 26.35 | H33: =C33/$H$45 -> 13.533007 | I33: 0 | J33: =E33/$I$44 -> 8.1713906 | L33: special_gun09 | M33: =M10*($H$44/$H$48) -> 256.58702 | N33: =N10*($H$44/$H$48) -> 0 | O33: =O10*($H$44/$H$48) -> 70.561431 | P33: 9
A34: ;rh_gun02, 6, 316.2 - 0 - 65.88 | B34: 6 | C34: 316.2 | D34: 0 | E34: 65.88 | F34: 33 | G34: ;rh_gun02, 6, 316.2 - 0 - 65.88 | H34: =C34/$H$45 -> 60.869656 | I34: 0 | J34: =E34/$I$44 -> 20.430027 | L34: special_gun10 | M34: =M11*($H$44/$H$48) -> 282.24572 | N34: =N11*($H$44/$H$48) -> 0 | O34: =O11*($H$44/$H$48) -> 57.73208 | P34: 10
A35: ;co_gun01, 1, 14.7 - 0 - 4.58 | B35: 1 | C35: 14.7 | D35: 0 | E35: 4.58 | F35: 34 | G35: ;co_gun01, 1, 14.7 - 0 - 4.58 | H35: =C35 -> 14.7 | I35: 0 | J35: =E35/$I$39 -> 4.58 | L35: special_gun11 | M35: =M12*($H$44/$H$48) -> 230.92832 | N35: =N12*($H$44/$H$48) -> 0 | O35: =O12*($H$44/$H$48) -> 64.146755 | P35: 11
A36: ;co_gun02, 2, 4.6 - 153 - 9.18 | B36: 2 | C36: 14.7 | D36: 153 | E36: 9.18 | F36: 35 | G36: ;co_gun02, 2, 4.6 - 153 - 9.18 | H36: =C36/$H$40 -> 9.6078431 | I36: =D36/H40 -> 100 | J36: =E36/$I$40 -> 7.344 | L36: special_gun12 | M36: =M13*($H$44/$H$48) -> 153.95221 | N36: =N13*($H$44/$H$48) -> 0 | O36: =O13*($H$44/$H$48) -> 38.488053 | P36: 12
L37: special_gun13 | M37: =M14*($H$44/$H$48) -> 282.24572 | N37: =N14*($H$44/$H$48) -> 0 | O37: =O14*($H$44/$H$48) -> 70.561431 | P37: 13
A38: Coefficients: | G38: Multipliers | I38: power_usage | L38: special_gun14 | M38: =M15*($H$44/$H$48) -> 307.90443 | N38: =N15*($H$44/$H$48) -> 0 | O38: =O15*($H$44/$H$48) -> 76.976106 | P38: 14
A39: Relate one for prevoius | B39: 1 | C39: 1 | D39: Same as Hull dmg | E39: 1 | G39: =C39 -> 1 | H39: =1 -> 1 | I39: =1 -> 1 | L39: special_gun15 | M39: =M16*($H$44/$H$48) -> 256.58702 | N39: =N16*($H$44/$H$48) -> 0 | O39: =O16*($H$44/$H$48) -> 70.561431 | P39: 15
A40: Следующий относ-но предыдущего | B40: 2 | C40: 1.53 | E40: 1.25 | G40: =C40*C39 -> 1.53 | H40: =C40 -> 1.53 | I40: =E40 -> 1.25
...

Sheet Лист2
A1: Name\Class: | B1: 1 | C1: 2 | D1: 3 | E1: 4 | F1: 5 | G1: 6 | I1: 7
A2: Hull Damage | B2: =Лист1!H15 -> 13.345585 | C2: =B2*Лист1!H40 -> 20.418746 | D2: =$B$2*Лист1!$H41 -> 24.91087 | E2: =$B$2*Лист1!$H42 -> 31.611894 | F2: =$B$2*Лист1!$H43 -> 40.4 | G2: =$B$2*Лист1!$H44 -> 52.52 | I2: =$B$2*Лист1!$H45 -> 69.3264
A3: Shield Damage | B3: =Лист1!I15 -> 0 | C3: =B3*Лист1!H40 -> 0 | D3: =$B$3*Лист1!$H41 -> 0 | E3: =$B$3*Лист1!$H42 -> 0 | F3: =$B$3*Лист1!$H43 -> 0 | G3: =$B$3*Лист1!$H44 -> 0 | I3: =$B$3*Лист1!$H45 -> 0
A4: Energy usage | B4: =Лист1!J15 -> 5.1072276 | C4: =B4*Лист1!I40 -> 6.3840346 | D4: =$B$4*Лист1!I41 -> 7.7821381 | E4: =$B$4*Лист1!I42 -> 9.8825372 | F4: =$B$4*Лист1!I43 -> 12.62 | G4: =$B$4*Лист1!I44 -> 16.4691 | I4: =$B$4*Лист1!K45 -> 0
A6: rh_gun01
B13: Lib | C13: Bret | D13: Kus | E13: Rh | F13: Pir | G13: Bw | H13: Cors | I13: Civ | J13: Bhunter | L13: Lvl6 | M13: Lib | N13: Bret | O13: Kus | P13: Rh | Q13: Pir | R13: Bw | S13: Cors | T13: Civ | U13: Bhunter | W13: Order | X13: Nomads
A14: Armor:
A16: Light | B16: 1300 | C16: 2100 | D16: 2800 | E16: 4500 | F16: 1900 | G16: 1800 | H16: 2400 | I16: 3300 | J16: 1800 | M16: =B16*$N$34 -> 2860 | N16: =$N$31*C16 -> 2940 | O16: =D16*N29 -> 2800 | P16: =E16*N26 -> 2700 | Q16: =F16*$N$32 -> 3040 | R16: =G16*N32 -> 2880 | S16: =H16*N30 -> 2880 | T16: =I16*N28 -> 2970 | U16: =J16*N32 -> 2880 | W16: 1 | X16: 1
A17: Heavy | B17: 1600 | C17: 2600 | D17: 3600 | E17: 5800 | F17: 3600 | G17: 4900 | H17: 9200 | I17: 6200 | J17: 3600 | M17: =B17*$N$37 -> 5600 | N17: =$N$34*C17 -> 5720 | O17: =D17*N32 -> 5760 | P17: =E17 -> 5800 | Q17: =F17*$N$32 -> 5760 | R17: =G17*N30 -> 5880 | S17: =H17*N26 -> 5520 | T17: =I17*N28 -> 5580 | U17: =J17*N32 -> 5760 | W17: 4200 | X17: 4000
A18: Vheavy | B18: 1 | C18: 1 | D18: 1 | E18: 1 | F18: 1 | G18: 10800 | H18: 12600 | I18: 9900 | J18: 7900 | M18: =M17*$N$33 -> 10640 | N18: =N17*$N$33 -> 10868 | O18: =O17*$N$33 -> 10944 | P18: =P17*$N$33 -> 11020 | Q18: =Q17*$N$33 -> 10944 | R18: =G18*N29 -> 10800 | S18: =H18*N28 -> 11340 | T18: =I18*N29 -> 9900 | U18: =J18*N30 -> 9480 | W18: 1 | X18: 1
A19: Freighter | B19: 1600 | C19: 2200 | D19: 3600 | E19: 5800 | F19: 2200 | G19: 3600 | H19: 1 | I19: 1 | J19: 1 | M19: =B19*$N$40 -> 8960 | N19: =$N$38*C19 -> 9020 | O19: =D19*$N$35 -> 9360 | P19: =E19*N32 -> 9280 | Q19: =F19*$N$38 -> 9020 | R19: =G19*N35 -> 9360 | S19: =Q19 -> 9020 | T19: =N19 -> 9020 | U19: =M19 -> 8960 | W19: 1 | X19: 1
A21: Cargo:
A23: Light | B23: 25 | C23: 30 | D23: 35 | E23: 45 | F23: 35 | G23: 35 | H23: 35 | I23: 45 | J23: 35 | L23: Armor Updates: | W23: Order | X23: Nomads
A24: Heavy | B24: 30 | C24: 35 | D24: 40 | E24: 50 | F24: 40 | G24: 45 | H24: 45 | I24: 60 | J24: 45 | L24: -5 | N24: 0.25
A25: Vheavy | B25: 0 | C25: 0 | D25: 0 | E25: 0 | F25: 0 | G25: 70 | H25: 70 | I25: 70 | J25: 70 | L25: -4 | N25: 0.5
A26: Freighter | B26: 80 | C26: 125 | D26: 175 | E26: 250 | F26: 90 | G26: 275 | H26: 0 | I26: 0 | J26: 0 | L26: -3 | N26: 0.6 | W26: =W27*N25 -> 2940 | X26: =X27*N25 -> 2400
L27: -2 | N27: 0.7 | W27: =W17*N31 -> 5880 | X27: =X17*N30 -> 4800
A28: Nano\Shield | L28: -1 | N28: 0.9 | W28: =W27*N33 -> 11172 | X28: =X27*N33 -> 9120
L29: 0 | N29: 1 | W29: 1 | X29: 1
A30: Light | B30: 12 | C30: 15 | D30: 23 | E30: 33 | F30: 14 | G30: 15 | H30: 20 | I30: 26 | J30: 15 | L30: 1 | N30: 1.2 | P30: 1.3
A31: Heavy | B31: 14 | C31: 20 | D31: 26 | E31: 38 | F31: 26 | G31: 33 | H31: 55 | I31: 43 | J31: 26 | L31: 2 | N31: 1.4
A32: Vheavy | B32: 0 | C32: 0 | D32: 0 | E32: 0 | F32: 0 | G32: 63 | H32: 71 | I32: 63 | J32: 49 | L32: 3 | N32: 1.6
A33: Freighter | B33: 12 | C33: 15 | D33: 23 | E33: 33 | F33: 15 | G33: 23 | H33: 0 | I33: 0 | J33: 0 | L33: 4 | N33: 1.9
L34: 5 | N34: 2.2
A35: Weapon max Class | L35: 6 | N35: 2.6
L36: 7 | N36: 3
A37: Light | B37: 3 | C37: 4 | D37: 6 | E37: 7 | F37: 4 | G37: 4 | H37: 5 | I37: 6 | J37: 4 | L37: 8 | N37: 3.5
A38: Heavy | B38: 4 | C38: 5 | D38: 6 | E38: 8 | F38: 6 | G38: 7 | H38: 9 | I38: 8 | J38: 6 | L38: 9 | N38: 4.1
A39: Vheavy | B39: 0 | C39: 0 | D39: 0 | E39: 0 | F39: 0 | G39: 10 | H39: 10 | I39: 10 | J39: 9 | L39: 10 | N39: 4.8
A40: Freighter | B40: 3 | C40: 4 | D40: 6 | E40: 7 | F40: 4 | G40: 6 | H40: 0 | I40: 0 | J40: 0 | L40: 11 | N40: 5.6
L41: 12 | N41: 6.6
A42: Then: | L42: 13 | N42: 7.7
A43: Power generators | B43: Lib | C43: Bret | D43: Kus | E43: Rh | F43: Pir | G43: Bw | H43: Cors | I43: Civ | J43: Bhunter | K43: Order | L43: 14
A44: capacity | L44: 15
L45: 16
A46: Light | B46: 1300 | C46: 2100 | D46: 2900 | E46: 4700 | F46: 1500 | G46: 1800 | H46: 2500 | I46: 3400 | J46: 1800 | K46: 1 | L46: 17 | N46: 14.4
A47: Heavy | B47: 1500 | C47: 2500 | D47: 3400 | E47: 5400 | F47: 3400 | G47: 4700 | H47: 8900 | I47: 6400 | J47: 3400 | K47: 4000 | L47: 18
A48: Vheavy | B48: 1 | C48: 1 | D48: 1 | E48: 1 | F48: 1 | G48: 10400 | H48: 11900 | I48: 10400 | J48: 7400 | K48: 1 | L48: 19
A49: Freighter | B49: 1300 | C49: 1800 | D49: 2700 | E49: 4700 | F49: 1800 | G49: 2900 | H49: 1 | I49: 1 | J49: 1 | K49: 1 | L49: 20
L50: 21 | N50: 27
...

Sheet Лист3
A1: Starlancer weapons | B1: Range | C1: Shield Damage | D1: Hull damage | E1: Speed | F1: Rounds\sec | G1: Power (per shot)
A3: Collapser guns | B3: 200 | C3: 25 | D3: 25 | E3: 1400 | F3: 6 | G3: 0
A4: Gatling plasma cannon | B4: 200 | C4: 10 | D4: 7 | E4: 1200 | F4: 5 | G4: 0
A5: Gattling lasers | B5: 140 | C5: 8.5 | D5: 6 | E5: 1800 | F5: 10 | G5: 2
A6: Laser cannon | B6: 200 | C6: 8 | D6: 8 | E6: 1600 | F6: 5.5 | G6: 2
A7: Meson blaster | B7: 150 | C7: 9 | D7: 9 | E7: 1300 | F7: 8 | G7: 2
A8: Neutron particle gun | B8: 200 | C8: 35 | D8: 30 | E8: 1300 | F8: 2 | G8: 15
A9: Nova cannon | B9: 200 | C9: 400 | D9: 400 | E9: 2000 | F9: 1 | G9: 0
A10: Proton cannon | B10: 200 | C10: 12 | D10: 11 | E10: 1500 | F10: 6 | G10: 3
A11: Pulse cannon | B11: 300 | C11: 8 | D11: 8 | E11: 1400 | F11: 8 | G11: 3
A12: Tachyon cannon | B12: 400 | C12: 20 | D12: 15 | E12: 1400 | F12: 5 | G12: 5
A13: Vulcan battery | B13: 300 | C13: 30 | D13: 35 | E13: 1700 | F13: 2 | G13: 0
A14: Flak gun | B14: 170 | C14: 15 | D14: 10 | E14: 2000 | F14: 7 | G14: 0
... A16: Main gun | B16: 2000 | C16: 1000 | D16: 1000 | E16: 1200 | F16: 1 | G16: 0
A19: Adapted for Freelancer | B19: lifetime | C19: energy_damage | D19: hull_damage | E19: muzzle_velocity | F19: refire_delay | G19: power_usage
A20: star_gun_collapser | B20: =$B$38*(B3/E3) -> 1.4285714 | E20: =0.5*E3 -> 700 | F20: =1/F3 -> 0.16666667
A21: star_gun_gatplas | B21: =$B$38*(B4/E4) -> 1.6666667 | E21: =0.5*E4 -> 600 | F21: =1/F4 -> 0.2
A22: star_gun_gatlas | B22: =$B$38*(B5/E5) -> 0.77777778 | E22: =0.5*E5 -> 900 | F22: =1/F5 -> 0.1
A23: star_gun_laser | B23: =$B$38*(B6/E6) -> 1.25 | E23: =0.5*E6 -> 800 | F23: =1/F6 -> 0.18181818
A24: star_gun_mesbla | B24: =$B$38*(B7/E7) -> 1.1538462 | E24: =0.5*E7 -> 650 | F24: =1/F7 -> 0.125
A25: star_gun_neupart | B25: =$B$38*(B8/E8) -> 1.5384615 | E25: =0.5*E8 -> 650 | F25: =1/F8 -> 0.5
A26: star_gun_ion | B26: =$B$38*(B9/E9) -> 1 | E26: =0.5*E9 -> 1000 | F26: =1/F9 -> 1
A27: star_gun_proton | B27: =$B$38*(B10/E10) -> 1.3333333 | E27: =0.5*E10 -> 750 | F27: =1/F10 -> 0.16666667
A28: star_gun_pulse | B28: =$B$38*(B11/E11) -> 2.1428571 | E28: =0.5*E11 -> 700 | F28: =1/F11 -> 0.125
A29: star_gun_tachyon | B29: =$B$38*(B12/E12) -> 2.8571429 | E29: =0.5*E12 -> 700 | F29: =1/F12 -> 0.2
A30: star_gun_vulcanbat | B30: =$B$38*(B13/E13) -> 1.7647059 | E30: =0.5*E13 -> 850 | F30: =1/F13 -> 0.5
A32: Star_CoalTurBig_01
A33: Star_CoalTur1_01
A34: Star_CoalCapGun_01
A37: Coefficients | B37: lifetime | C37: energy_damage | D37: hull_damage | E37: muzzle_velocity | F37: refire_delay | G37: power_usage
B38: 10 | C38: 1 | D38: 1 | E38: =500/1400 -> 0.35714286 | F38: =1/36 -> 0.027777778 | G38: 1
A41: Freelancer\Starlancer range | B41: =2000/1000 -> 2

Sheet Лист4
A1: hull_damage = | B1: Barrels: | E1: refire_delay = | F1: lifetime =
B2: 1 | C2: 2 | D2: 3 | G2: 4
A3: gunboat_turret01 | B3: 108 | C3: =B3*0.5 -> 54 | D3: =B3/3 -> 36 | E3: 0.5 | G3: =B3/4 -> 27
A4: gunboat_turret02 | B4: 12 | C4: =B4*0.5 -> 6 | D4: =B4/3 -> 4 | E4: 0.1 | G4: =B4/4 -> 3
B5: 1 | C5: 2 | D5: 3 | G5: 4
A6: destroyer_turret01 | B6: =B11/2 -> 600 | C6: =B6*0.5 -> 300 | D6: =B6/3 -> 200 | E6: 2 | G6: =B6/4 -> 150
A7: destroyer_turret02 | B7: =B12/2 -> 120 | C7: =B7*0.5 -> 60 | D7: =B7/3 -> 40 | E7: 0.5 | G7: =B7/4 -> 30
A8: destroyer_turret03 | B8: =B13/2 -> 30 | C8: =B8*0.5 -> 15 | D8: =B8/3 -> 10 | E8: 0.5 | G8: =B8/4 -> 7.5
A9: destroyer_turret04 | B9: =B14/2 -> 15 | C9: =B9*0.5 -> 7.5 | D9: =B9/3 -> 5 | E9: 0.1 | G9: =B9/4 -> 3.75
B10: 1 | C10: 2 | D10: 3 | G10: 4
A11: battleship_turret01 | B11: 1200 | C11: =B11*0.5 -> 600 | D11: =B11/3 -> 400 | E11: 2 | G11: =B11/4 -> 300
A12: battleship_turret02 | B12: 240 | C12: =B12*0.5 -> 120 | D12: =B12/3 -> 80 | E12: 0.5 | G12: =B12/4 -> 60
A13: battleship_turret03 | B13: 60 | C13: =B13*0.5 -> 30 | D13: =B13/3 -> 20 | E13: 0.5 | G13: =B13/4 -> 15
A14: battleship_turret04 | B14: 30 | C14: =B14*0.5 -> 15 | D14: =B14/3 -> 10 | E14: 0.1 | G14: =B14/4 -> 7.5
B15: 1 | C15: 2 | D15: 3 | G15: 4
A16: gunboat_gun01 | B16: 1260 | C16: =B16/2 -> 630 | D16: =B16/3 -> 420 | E16: 2 | G16: =B16/4 -> 315
A17: cruiser_gun01 | B17: 1500 | C17: =B17/2 -> 750 | D17: =B17/3 -> 500 | E17: 2 | G17: =B17/4 -> 375
A18: battleship_gun01 | B18: 4800 | C18: =B18/2 -> 2400 | D18: =B18/3 -> 1600 | E18: 4 | G18: =B18/4 -> 1200
